Workbook

Sheet SUMMARY
A1: TEST CASE SPECIFICATION — SUMMARY
A3: Project Name | B3: Integrated Coding Education & Competitive Programming Platform
A4: Prepared By | B4: Team 2 - SE20A11
A5: Date | B5: 46204
A6: Version | B6: 2
A7: Total Modules | B7: 15
A8: Total Test Cases | B8: 129
A9: Total Entities | B9: 42
A11: Module | B11: Total Test Cases | C11: High | D11: Medium | E11: Low | F11: Passed | G11: Failed | H11: Pass Rate
A12: AUTH | B12: 2 | C12: 2 | D12: 0 | E12: 0 | F12: =COUNTIF(AUTH!H3:H4, "Pass") | G12: =COUNTIF(AUTH!H3:H4, "Fail") | H12: =F12/B12
A13: USER | B13: 12 | C13: 6 | D13: 3 | E13: 3 | F13: =COUNTIF(USER!H3:H14, "Pass") | G13: =COUNTIF(USER!H3:H14, "Fail") | H13: =F13/B13
A14: ADMIN | B14: 18 | C14: 8 | D14: 10 | E14: 0 | F14: =COUNTIF(ADMIN!H3:H20, "Pass") | G14: =COUNTIF(ADMIN!H3:H20, "Fail") | H14: =F14/B14
A15: CART | B15: 4 | C15: 4 | D15: 0 | E15: 0 | F15: =COUNTIF(CART!H3:H6, "Pass") | G15: =COUNTIF(CART!H3:H6, "Fail") | H15: =F15/B15
A16: CATEGORY | B16: 1 | C16: 1 | D16: 0 | E16: 0 | F16: =COUNTIF(CATEGORY!H3:H3, "Pass") | G16: =COUNTIF(CATEGORY!H3:H3, "Fail") | H16: =F16/B16
A17: PAYMENT | B17: 8 | C17: 5 | D17: 3 | E17: 0 | F17: =COUNTIF(PAYMENT!H3:H10, "Pass") | G17: =COUNTIF(PAYMENT!H3:H10, "Fail") | H17: =F17/B17
A18: COURSE | B18: 11 | C18: 5 | D18: 6 | E18: 0 | F18: =COUNTIF(COURSE!H3:H13, "Pass") | G18: =COUNTIF(COURSE!H3:H13, "Fail") | H18: =F18/B18
A19: QUIZ | B19: 4 | C19: 4 | D19: 0 | E19: 0 | F19: =COUNTIF(QUIZ!H3:H6, "Pass") | G19: =COUNTIF(QUIZ!H3:H6, "Fail") | H19: =F19/B19
A20: INSTRUCTOR | B20: 16 | C20: 9 | D20: 6 | E20: 1 | F20: =COUNTIF(INSTRUCTOR!H3:H18, "Pass") | G20: =COUNTIF(INSTRUCTOR!H3:H18, "Fail") | H20: =F20/B20
A21: AI | B21: 5 | C21: 3 | D21: 2 | E21: 0 | F21: =COUNTIF(AI!H3:H7, "Pass") | G21: =COUNTIF(AI!H3:H7, "Fail") | H21: =F21/B21
A22: JUDGE0 | B22: 2 | C22: 2 | D22: 0 | E22: 0 | F22: =COUNTIF(JUDGE0!H3:H4, "Pass") | G22: =COUNTIF(JUDGE0!H3:H4, "Fail") | H22: =F22/B22
A23: MODERATION | B23: 3 | C23: 2 | D23: 1 | E23: 0 | F23: =COUNTIF(MODERATION!H3:H5, "Pass") | G23: =COUNTIF(MODERATION!H3:H5, "Fail") | H23: =F23/B23
A24: RANKING | B24: 2 | C24: 2 | D24: 0 | E24: 0 | F24: =COUNTIF(RANKING!H3:H4, "Pass") | G24: =COUNTIF(RANKING!H3:H4, "Fail") | H24: =F24/B24
A25: PROBLEM | B25: 19 | C25: 10 | D25: 7 | E25: 2 | F25: =COUNTIF(PROBLEM!H3:H21, "Pass") | G25: =COUNTIF(PROBLEM!H3:H21, "Fail") | H25: =F25/B25
A26: CONTEST | B26: 22 | C26: 13 | D26: 7 | E26: 2 | F26: =COUNTIF(CONTEST!H3:H24, "Pass") | G26: =COUNTIF(CONTEST!H3:H24, "Fail") | H26: =F26/B26
A27: TOTAL | B27: =SUM(B12:B26) | C27: =SUM(C12:C26) | D27: =SUM(D12:D26) | E27: =SUM(E12:E26) | F27: =SUM(F12:F26) | G27: =SUM(G12:G26) | H27: =F27/B27

Sheet AUTH
A1: AUTH MODULE — Test Case Specification
A2: Test Case ID | B2: Function Name | C2: Test Objective | D2: Pre-conditions | E2: Test Steps | F2: Expected Result | G2: Actual Result | H2: Status | I2: Priority
A3: TC_AUTH_01 | B3: Login | C3: Verify that a registered user can log in with valid credentials and receive authentication tokens | D3: 1. A valid user account (username: `john_doe`) exists in the system with status `ACTIVE`. 2. The user's password is correctly hashed and stored in the database. | E3: 1. Navigate to the Login page. 2. Enter a valid username and correct password. 3. Click the "Login" button. 4. Observe the system response and check for session tokens. | F3: - The system returns HTTP 200 OK. - An access token and a refresh token are issued and set as HTTP-only cookies. - The user is redirected to the home/dashboard page. | G3: As expected: The system returns HTTP 200 OK. - An access token and a refresh token are issued and set as HTTP-only cookies. - The user is redirected to the home/dashboard page. | H3: Pass | I3: High
A4: TC_AUTH_02 | B4: Register | C4: Verify that a new user can create an account with valid, unique credentials | D4: 1. The username and email address to be registered do not already exist in the system. | E4: 1. Navigate to the Registration page. 2. Enter a unique username, a valid email, and a strong password. 3. Click the "Register" button. 4. Observe the system response. | F4: - The system returns HTTP 200 OK. - A success message "Register account successfully" is displayed. - A new user record is created in the database with status `ACTIVE`. | G4: As expected: The system returns HTTP 200 OK. - A success message "Register account successfully" is displayed. - A new user record is created in the database with status `ACTIVE`. | H4: Pass | I4: High

Sheet USER
A1: USER MODULE — Test Case Specification
A2: Test Case ID | B2: Function Name | C2: Test Objective | D2: Pre-conditions | E2: Test Steps | F2: Expected Result | G2: Actual Result | H2: Status | I2: Priority
A3: TC_USER_01 | B3: Get All Users (Admin) | C3: Verify that an Administrator can view the complete list of all registered users | D3: 1. The actor is logged in with the `ADMIN` role. 2. At least one user account exists in the system. | E3: 1. Log in as an Administrator. 2. Navigate to the User Management section. 3. Request the full user list. | F3: - The system returns HTTP 200 OK. - A complete list of all user accounts is returned, including their username, email, status, and registration date. | G3: As expected: The system returns HTTP 200 OK. - A complete list of all user accounts is returned, including their username, email, status, and registration date. | H3: Pass | I3: High
A4: TC_USER_02 | B4: Lock/Unlock User (Admin) | C4: Verify that an Administrator can lock a user account and provide a reason | D4: 1. The actor is logged in with the `ADMIN` role. 2. The target user account (ID: 100) exists and has status `ACTIVE`. | E4: 1. Log in as an Administrator. 2. Navigate to the User Management section. 3. Select the target user. 4. Submit a lock action with the reason "Violated community guidelines". 5. Observe the updated user status. | F4: - The system returns HTTP 200 OK. - The target user's status is updated to `LOCKED`. - The `lockReason` field is saved as "Violated community guidelines". - The user can no longer log in. | G4: As expected: The system returns HTTP 200 OK. - The target user's status is updated to `LOCKED`. - The `lockReason` field is saved as "Violated community guidelines". - The user can no longer log in. | H4: Pass | I4: High
A5: TC_USER_03 | B5: Get Dashboard Stats (No Auth) | C5: Verify that the dashboard stats endpoint is accessible without authentication and returns a default empty response | D5: 1. The actor is not logged in (unauthenticated/guest user). | E5: 1. Send a request to the dashboard stats endpoint without any authentication token. | F5: - The system returns HTTP 200 OK. - The response body contains stat fields initialized to default/zero values (no user-specific data is exposed). | G5: As expected: The system returns HTTP 200 OK. - The response body contains stat fields initialized to default/zero values (no user-specific data is exposed). | H5: Pass | I5: Medium
A6: TC_USER_04 | B6: Get Dashboard Stats (Authenticated) | C6: Verify that an authenticated user can retrieve their personalized dashboard statistics | D6: 1. The actor is logged in as a regular User. 2. The user has at least some activity history (submissions, enrollments). | E6: 1. Log in as a User. 2. Navigate to the personal Dashboard page. | F6: - The system returns HTTP 200 OK. - The response message is "Get dashboard stats successfully". - The response payload contains the user's actual statistics (e.g., problems solved, enrolled courses, streak). | G6: As expected: The system returns HTTP 200 OK. - The response message is "Get dashboard stats successfully". - The response payload contains the user's actual statistics (e.g., problems solved, enrolled courses, streak). | H6: Pass | I6: Medium
A7: TC_USER_05 | B7: Get User Activities (Valid Year) | C7: Verify that a user can retrieve their daily coding activity heatmap for a specific year | D7: 1. The actor is logged in as a regular User. 2. The user has daily activity records for the year 2026. | E7: 1. Log in as a User. 2. Navigate to the Activity section and provide the year `2026` as a filter. | F7: - The system returns HTTP 200 OK. - The response message is "Get user activities successfully". - The response contains a list of daily activity entries for the specified year. | G7: As expected: The system returns HTTP 200 OK. - The response message is "Get user activities successfully". - The response contains a list of daily activity entries for the specified year. | H7: Pass | I7: Medium
A8: TC_USER_06 | B8: Get User Activities (Missing Year) | C8: Verify that the system returns an error when the required `year` parameter is missing | D8: 1. The actor is logged in as a regular User. | E8: 1. Log in as a User. 2. Send a request to the activities endpoint without providing the `year` query parameter. | F8: - The system returns HTTP 500 Internal Server Error. - The error indicates a missing required request parameter. - No user data is returned. | G8: As expected: The system returns HTTP 500 Internal Server Error. - The error indicates a missing required request parameter. - No user data is returned. | H8: Pass | I8: Low
A9: TC_USER_07 | B9: Get Enrolled Courses (Authenticated) | C9: Verify that a logged-in user can retrieve their list of enrolled courses | D9: 1. The actor is logged in as a regular User. 2. The user is enrolled in at least one course. | E9: 1. Log in as a User. 2. Navigate to the "My Courses" or enrolled courses section. | F9: - The system returns HTTP 200 OK. - The response message is "Get enrolled courses successfully". - The `result` array contains the list of courses the user is enrolled in, with course title, status, and progress. | G9: As expected: The system returns HTTP 200 OK. - The response message is "Get enrolled courses successfully". - The `result` array contains the list of courses the user is enrolled in, with course title, status, and progress. | H9: Pass | I9: High
A10: TC_USER_08 | B10: Get Enrolled Courses (Anonymous) | C10: Verify that the enrolled courses endpoint returns an empty list for anonymous (unauthenticated) users | D10: 1. The actor is not logged in (guest user). | E10: 1. Without logging in, send a request to the enrolled courses endpoint. | F10: - The system returns HTTP 200 OK. - The `result` array is empty, as no user context is available. - No error or unauthorized response is returned. | G10: As expected: The system returns HTTP 200 OK. - The `result` array is empty, as no user context is available. - No error or unauthorized response is returned. | H10: Pass | I10: Low
A11: TC_USER_09 | B11: Get Submission Statistics (Authenticated) | C11: Verify that a logged-in user can retrieve their coding submission statistics | D11: 1. The actor is logged in as a regular User. 2. The user has submitted at least one code solution. | E11: 1. Log in as a User. 2. Navigate to the Submission Statistics section. | F11: - The system returns HTTP 200 OK. - The response message is "Get submission statistics successfully". - The payload contains `totalSubmissions`, `totalAccepted`, and acceptance rate. | G11: As expected: The system returns HTTP 200 OK. - The response message is "Get submission statistics successfully". - The payload contains `totalSubmissions`, `totalAccepted`, and acceptance rate. | H11: Pass | I11: High
A12: TC_USER_10 | B12: Get Submission Statistics (Anonymous) | C12: Verify that the submission statistics endpoint returns zeroed guest stats for unauthenticated users | D12: 1. The actor is not logged in (guest user). | E12: 1. Without logging in, send a request to the submission statistics endpoint. | F12: - The system returns HTTP 200 OK. - The response contains default/zero values (e.g., `totalSubmissions = 0`). - No user-specific data is exposed. | G12: As expected: The system returns HTTP 200 OK. - The response contains default/zero values (e.g., `totalSubmissions = 0`). - No user-specific data is exposed. | H12: Pass | I12: Low
A13: TC_USER_11 | B13: Get My Info | C13: Verify that an authenticated user can retrieve their own profile information | D13: 1. The actor is logged in as a regular User. | E13: 1. Log in as a User. 2. Navigate to the Profile / "My Info" section. | F13: - The system returns HTTP 200 OK. - The response message is "User info retrieved successfully". - The payload contains the user's `displayName`, `email`, `avatarUrl`, and `status`. | G13: As expected: The system returns HTTP 200 OK. - The response message is "User info retrieved successfully". - The payload contains the user's `displayName`, `email`, `avatarUrl`, and `status`. | H13: Pass | I13: High
A14: TC_USER_12 | B14: Change Password | C14: Verify that an authenticated user can successfully change their password using the correct old password | D14: 1. The actor is logged in as a regular User. 2. The user knows their current password. | E14: 1. Log in as a User. 2. Navigate to the Change Password section. 3. Enter the correct old password and a new strong password. 4. Confirm the new password and submit. | F14: - The system returns HTTP 200 OK. - The response message is "Password changed successfully". - The user's password hash is updated in the database. - Future login attempts using the old password will fail. | G14: Failed: The system returns HTTP 200 OK and reports success, but due to session synchronization lag (Redis cache update delay), the old password session remains active and can still be used to log in for up to 15 minutes after the change. | H14: Fail | I14: High

Sheet ADMIN
A1: ADMIN MODULE — Test Case Specification
A2: Test Case ID | B2: Function Name | C2: Test Objective | D2: Pre-conditions | E2: Test Steps | F2: Expected Result | G2: Actual Result | H2: Status | I2: Priority
A3: TC_ADMIN_01 | B3: Get All Courses (Admin) | C3: Verify that an Administrator can view the full list of courses submitted to the platform | D3: 1. The actor is logged in with the `ADMIN` role. 2. At least one course exists in the system. | E3: 1. Log in as an Administrator. 2. Navigate to the Course Management section. | F3: - The system returns HTTP 200 OK. - A list of all courses is returned, including their title, status (DRAFTS, PENDING_ADMIN, APPROVED, REJECTED), instructor name, and chapter count. | G3: As expected: The system returns HTTP 200 OK. - A list of all courses is returned, including their title, status (DRAFTS, PENDING_ADMIN, APPROVED, REJECTED), instructor name, and chapter count. | H3: Pass | I3: High
A4: TC_ADMIN_02 | B4: Approve Course (Valid Status) | C4: Verify that an Administrator can approve a course that is pending review | D4: 1. The actor is logged in with the `ADMIN` role. 2. A target course exists with status `PENDING_ADMIN`. 3. The course has passed the AI moderation check. | E4: 1. Log in as an Administrator. 2. Navigate to the Course Management section. 3. Select the target pending course. 4. Submit an approval with a positive admin note. | F4: - The system returns HTTP 200 OK. - The target course status changes to `APPROVED`. - The admin note is saved against the course record. - The course becomes publicly visible to users. | G4: Failed: The course status successfully changed to APPROVED in the database, but it did not become visible in the public course list due to a missing cache eviction trigger (Redis course list cache not cleared). | H4: Fail | I4: High
A5: TC_ADMIN_03 | B5: Approve Course (Invalid Status) | C5: Verify that the system rejects a course approval request with an invalid status value | D5: 1. The actor is logged in with the `ADMIN` role. 2. A target course exists in the system. | E5: 1. Log in as an Administrator. 2. Navigate to the Course Management section. 3. Submit an approval action with an unrecognized status value (e.g., "INVALID_STATUS"). | F5: - The system returns HTTP 400 Bad Request. - The error code `4000` is returned in the response. - The course status remains unchanged. - An error message indicating the invalid status is returned. | G5: As expected: The system returns HTTP 400 Bad Request. - The error code `4000` is returned in the response. - The course status remains unchanged. - An error message indicating the invalid status is returned. | H5: Pass | I5: High
A6: TC_ADMIN_04 | B6: Get Dashboard Stats (Admin) | C6: Verify that the Admin dashboard displays accurate platform-wide summary statistics | D6: 1. The actor is logged in with the `ADMIN` role. 2. The system has existing data (users, orders, courses). | E6: 1. Log in as an Administrator. 2. Navigate to the Admin Dashboard page. | F6: - The system returns HTTP 200 OK. - The response contains key platform metrics: total registered users, total revenue generated, total active courses, and new registrations. | G6: As expected: The system returns HTTP 200 OK. - The response contains key platform metrics: total registered users, total revenue generated, total active courses, and new registrations. | H6: Pass | I6: Medium
A7: TC_ADMIN_05 | B7: Get Recent Deposits (Admin) | C7: Verify that an Administrator can view the most recent deposit transactions across all users | D7: 1. The actor is logged in with the `ADMIN` role. 2. At least one deposit transaction exists in the system. | E7: 1. Log in as an Administrator. 2. Navigate to the Financial / Recent Deposits section. | F7: - The system returns HTTP 200 OK. - A list of the most recent deposit records is returned, including user name, amount, transaction code, status, and timestamp. | G7: As expected: The system returns HTTP 200 OK. - A list of the most recent deposit records is returned, including user name, amount, transaction code, status, and timestamp. | H7: Pass | I7: Medium
A8: TC_ADMIN_06 | B8: Get Monthly Financial Records | C8: Verify that an Administrator can view month-by-month financial performance data | D8: 1. The actor is logged in with the `ADMIN` role. 2. Order and transaction data spanning multiple months exists. | E8: 1. Log in as an Administrator. 2. Navigate to the Financial Reports > Monthly Records section. | F8: - The system returns HTTP 200 OK. - A breakdown of financial data is returned per month, including total revenue, platform fees, and payout amounts. | G8: As expected: The system returns HTTP 200 OK. - A breakdown of financial data is returned per month, including total revenue, platform fees, and payout amounts. | H8: Pass | I8: High
A9: TC_ADMIN_07 | B9: Get Top Revenue Courses | C9: Verify that an Administrator can identify the highest revenue-generating courses | D9: 1. The actor is logged in with the `ADMIN` role. 2. At least one completed order exists. | E9: 1. Log in as an Administrator. 2. Navigate to the Financial Reports > Top Courses section. | F9: - The system returns HTTP 200 OK. - A ranked list of courses is returned, ordered by total revenue generated, including course title, instructor name, and revenue amount. | G9: As expected: The system returns HTTP 200 OK. - A ranked list of courses is returned, ordered by total revenue generated, including course title, instructor name, and revenue amount. | H9: Pass | I9: High
A10: TC_ADMIN_08 | B10: Get Financial Details | C10: Verify that an Administrator can view the aggregated financial summary of the platform | D10: 1. The actor is logged in with the `ADMIN` role. | E10: 1. Log in as an Administrator. 2. Navigate to the Financial Reports > Details section. | F10: - The system returns HTTP 200 OK. - The response contains aggregate financial figures: total gross revenue, total platform commission, total instructor payout amount. | G10: As expected: The system returns HTTP 200 OK. - The response contains aggregate financial figures: total gross revenue, total platform commission, total instructor payout amount. | H10: Pass | I10: High
A11: TC_ADMIN_09 | B11: Get Orders (Default Pagination) | C11: Verify that an Administrator can view orders using default pagination settings | D11: 1. The actor is logged in with the `ADMIN` role. 2. At least one order exists in the system. | E11: 1. Log in as an Administrator. 2. Navigate to the Order Management section without applying any filters. | F11: - The system returns HTTP 200 OK. - The first page of orders is returned with a default page size (10 records). - Each record includes order ID, user, total amount, status, and date. | G11: As expected: The system returns HTTP 200 OK. - The first page of orders is returned with a default page size (10 records). - Each record includes order ID, user, total amount, status, and date. | H11: Pass | I11: Medium
A12: TC_ADMIN_10 | B12: Get Orders (Date Filter) | C12: Verify that an Administrator can filter orders by a specific date range | D12: 1. The actor is logged in with the `ADMIN` role. 2. Orders exist within the date range being queried. | E12: 1. Log in as an Administrator. 2. Navigate to the Order Management section. 3. Apply a date range filter (e.g., from 2026-01-01 to 2026-07-15) and a specific page/size. | F12: - The system returns HTTP 200 OK. - Only orders created within the specified date range are returned. | G12: As expected: The system returns HTTP 200 OK. - Only orders created within the specified date range are returned. | H12: Pass | I12: Medium
A13: TC_ADMIN_11 | B13: Get Awards (Default Pagination) | C13: Verify that an Administrator can view platform award/prize records with default pagination | D13: 1. The actor is logged in with the `ADMIN` role. | E13: 1. Log in as an Administrator. 2. Navigate to the Financial Reports > Awards section without applying filters. | F13: - The system returns HTTP 200 OK. - The first page of award records is returned with default pagination. | G13: As expected: The system returns HTTP 200 OK. - The first page of award records is returned with default pagination. | H13: Pass | I13: Medium
... A20: TC_ADMIN_18 | B20: Get Instructor Applications (Admin) | C20: Verify that an Administrator can view all instructor applications including AI evaluation results | D20: 1. The actor is logged in with the `ADMIN` role. 2. At least one instructor application exists (status: PENDING, APPROVED, or REJECTED). | E20: 1. Log in as an Administrator. 2. Navigate to the Instructor Applications section. | F20: - The system returns HTTP 200 OK. - A list of all applications is returned, including the applicant's name, AI evaluation score (`aiScore`), AI recommendation, and current status. | G20: As expected: The system returns HTTP 200 OK. - A list of all applications is returned, including the applicant's name, AI evaluation score (`aiScore`), AI recommendation, and current status. | H20: Pass | I20: High

Sheet CART
A1: CART MODULE — Test Case Specification
A2: Test Case ID | B2: Function Name | C2: Test Objective | D2: Pre-conditions | E2: Test Steps | F2: Expected Result | G2: Actual Result | H2: Status | I2: Priority
A3: TC_CART_01 | B3: View Cart | C3: Verify that a logged-in user can view the list of courses currently in their shopping cart | D3: 1. The actor is logged in as a regular User. 2. The user's cart contains at least one course (Course ID: 10). | E3: 1. Log in as a User. 2. Navigate to the Shopping Cart page. | F3: - The system returns HTTP 200 OK. - A list of course IDs (and associated course details) currently in the user's cart is returned. | G3: As expected: The system returns HTTP 200 OK. - A list of course IDs (and associated course details) currently in the user's cart is returned. | H3: Pass | I3: High
A4: TC_CART_02 | B4: Add Course to Cart | C4: Verify that a logged-in user can successfully add a course to their shopping cart | D4: 1. The actor is logged in as a regular User. 2. The target course (ID: 10) exists, is published, and has not already been purchased or added to the cart by this user. | E4: 1. Log in as a User. 2. Browse to a course detail page. 3. Click "Add to Cart" button. | F4: - The system returns HTTP 200 OK. - The success message "Course added to cart successfully" is displayed. - The course now appears in the user's cart. | G4: As expected: The system returns HTTP 200 OK. - The success message "Course added to cart successfully" is displayed. - The course now appears in the user's cart. | H4: Pass | I4: High
A5: TC_CART_03 | B5: Remove Course from Cart | C5: Verify that a logged-in user can remove a specific course from their shopping cart | D5: 1. The actor is logged in as a regular User. 2. The target course (ID: 10) is already present in the user's cart. | E5: 1. Log in as a User. 2. Navigate to the Shopping Cart page. 3. Click "Remove" on the target course. | F5: - The system returns HTTP 200 OK. - The success message "Course removed from cart successfully" is displayed. - The course is no longer present in the user's cart. | G5: As expected: The system returns HTTP 200 OK. - The success message "Course removed from cart successfully" is displayed. - The course is no longer present in the user's cart. | H5: Pass | I5: High
A6: TC_CART_04 | B6: Clear Cart | C6: Verify that a logged-in user can clear all items from their shopping cart at once | D6: 1. The actor is logged in as a regular User. 2. The user's cart contains at least one course item. | E6: 1. Log in as a User. 2. Navigate to the Shopping Cart page. 3. Click "Clear Cart" or "Remove All" button. | F6: - The system returns HTTP 200 OK. - The success message "Cart cleared successfully" is displayed. - The user's cart is now empty. | G6: As expected: The system returns HTTP 200 OK. - The success message "Cart cleared successfully" is displayed. - The user's cart is now empty. | H6: Pass | I6: High

Sheet CATEGORY
A1: CATEGORY MODULE — Test Case Specification
A2: Test Case ID | B2: Function Name | C2: Test Objective | D2: Pre-conditions | E2: Test Steps | F2: Expected Result | G2: Actual Result | H2: Status | I2: Priority
A3: TC_CATEGORY_01 | B3: Get All Categories | C3: Verify that the system returns all available course categories to any visitor without requiring authentication | D3: 1. At least one category record exists in the system. 2. The endpoint is publicly accessible (no authentication required). | E3: 1. Navigate to the Categories section or the course filter page (no login required). 2. Observe the list of categories displayed. | F3: - The system returns HTTP 200 OK. - A complete list of all active categories is returned, each including the category `id`, `name`, and `description`. | G3: As expected: The system returns HTTP 200 OK. - A complete list of all active categories is returned, each including the category `id`, `name`, and `description`. | H3: Pass | I3: High

Sheet PAYMENT
A1: PAYMENT MODULE — Test Case Specification
A2: Test Case ID | B2: Function Name | C2: Test Objective | D2: Pre-conditions | E2: Test Steps | F2: Expected Result | G2: Actual Result | H2: Status | I2: Priority
A3: TC_PAYMENT_01 | B3: Get Wallet Balance | C3: Verify that a logged-in user can view their current wallet balance | D3: 1. The actor is logged in as a regular User. 2. The user has an active wallet with a balance (e.g., 100.50 VND equivalent). | E3: 1. Log in as a User. 2. Navigate to the Wallet section. | F3: - The system returns HTTP 200 OK. - The response contains the user's current wallet balance (e.g., `100.50`). | G3: As expected: The system returns HTTP 200 OK. - The response contains the user's current wallet balance (e.g., `100.50`). | H3: Pass | I3: High
A4: TC_PAYMENT_02 | B4: Create Deposit Request | C4: Verify that a logged-in user can initiate a deposit (top-up) to their wallet via a payment gateway | D4: 1. The actor is logged in as a regular User. 2. The user has an active wallet. 3. The payment gateway (e.g., PayOS) is operational. | E4: 1. Log in as a User. 2. Navigate to the Wallet > Deposit section. 3. Enter the desired deposit amount and confirm. 4. Observe the system response. | F4: - The system returns HTTP 200 OK. - A payment checkout URL (`checkoutUrl`) is returned, which the user can follow to complete the payment. - A unique `transactionCode` is generated and stored with status `PENDING`. | G4: As expected: The system returns HTTP 200 OK. - A payment checkout URL (`checkoutUrl`) is returned, which the user can follow to complete the payment. - A unique `transactionCode` is generated and stored with status `PENDING`. | H4: Pass | I4: High
A5: TC_PAYMENT_03 | B5: Cancel Payment | C5: Verify that a user can cancel a pending payment transaction | D5: 1. The actor is logged in as a regular User. 2. A payment transaction with the given transaction code exists with status `PENDING`. | E5: 1. Log in as a User. 2. Navigate to the Transaction History section. 3. Select the pending transaction and click "Cancel". | F5: - The system returns HTTP 200 OK. - The response message is "Payment cancelled successfully". - The transaction status is updated to `CANCELLED`. - The wallet balance remains unchanged. | G5: As expected: The system returns HTTP 200 OK. - The response message is "Payment cancelled successfully". - The transaction status is updated to `CANCELLED`. - The wallet balance remains unchanged. | H5: Pass | I5: High
A6: TC_PAYMENT_04 | B6: Handle Payment Webhook | C6: Verify that the system correctly processes a successful payment notification from the payment gateway | D6: 1. A pending payment transaction exists in the system with a matching transaction code. 2. The payment gateway sends a webhook callback with a success code (`"00"`). | E6: 1. The payment gateway sends a POST request to the webhook endpoint with a success payload. 2. Observe the system's processing behavior. | F6: - The system returns HTTP 200 with `success = true`. - The corresponding payment transaction status is updated to `SUCCESS`. - The user's wallet balance is credited with the deposited amount. | G6: Failed: The system returns HTTP 200 with success = true, and the payment transaction status is updated to SUCCESS. However, the user's wallet balance was not credited because of a database lock timeout on the Wallet entity during concurrent requests (race condition). | H6: Fail | I6: High
A7: TC_PAYMENT_05 | B7: Checkout (Order from Cart) | C7: Verify that a logged-in user can place an order for courses currently in their cart | D7: 1. The actor is logged in as a regular User. 2. The user's cart contains at least two courses (IDs: 1, 2). 3. The user's wallet has sufficient balance to cover the total order amount. | E7: 1. Log in as a User. 2. Navigate to the Shopping Cart. 3. Review items and click "Checkout". 4. Confirm the purchase. | F7: - The system returns HTTP 200 OK. - The response message is "Order checkout completed successfully". - A new Order record is created with status `COMPLETED`. - The user is automatically enrolled in all purchased courses. - The corresponding amount is deducted from the user's wallet. | G7: As expected: The system returns HTTP 200 OK. - The response message is "Order checkout completed successfully". - A new Order record is created with status `COMPLETED`. - The user is automatically enrolled in all purchased courses. - The corresponding amount is deducted from the user's wallet. | H7: Pass | I7: High
A8: TC_PAYMENT_06 | B8: Get Purchase History | C8: Verify that a logged-in user can view a paginated list of their completed orders | D8: 1. The actor is logged in as a regular User. 2. The user has at least one completed order. | E8: 1. Log in as a User. 2. Navigate to the Purchase History section. 3. Observe the default first page (page=0, size=10). | F8: - The system returns HTTP 200 OK. - The response message is "Fetched purchase history successfully". - A paginated list of completed orders is returned, including order date, total amount, and course names. | G8: As expected: The system returns HTTP 200 OK. - The response message is "Fetched purchase history successfully". - A paginated list of completed orders is returned, including order date, total amount, and course names. | H8: Pass | I8: Medium
A9: TC_PAYMENT_07 | B9: Get Wallet Transactions | C9: Verify that a logged-in user can view a paginated history of their wallet balance changes (top-ups and deductions) | D9: 1. The actor is logged in as a regular User. 2. The user has at least one wallet transaction (deposit or deduction). | E9: 1. Log in as a User. 2. Navigate to the Wallet > Transaction History section. | F9: - The system returns HTTP 200 OK. - The response message is "Get wallet transaction statistics successfully". - A paginated list of wallet transactions is returned, with type (ADD/DEDUCT), amount, status, and date. | G9: As expected: The system returns HTTP 200 OK. - The response message is "Get wallet transaction statistics successfully". - A paginated list of wallet transactions is returned, with type (ADD/DEDUCT), amount, status, and date. | H9: Pass | I9: Medium
A10: TC_PAYMENT_08 | B10: Get Payment Transactions | C10: Verify that a logged-in user can view a paginated history of their direct payment (deposit) transactions | D10: 1. The actor is logged in as a regular User. 2. The user has made at least one deposit via the payment gateway. | E10: 1. Log in as a User. 2. Navigate to the Wallet > Deposit History section. | F10: - The system returns HTTP 200 OK. - The response message is "Get payment transaction statistics successfully". - A paginated list of deposit transactions is returned, including transaction code, amount, status, and date. | G10: As expected: The system returns HTTP 200 OK. - The response message is "Get payment transaction statistics successfully". - A paginated list of deposit transactions is returned, including transaction code, amount, status, and date. | H10: Pass | I10: Medium

Sheet COURSE
A1: COURSE MODULE — Test Case Specification
A2: Test Case ID | B2: Function Name | C2: Test Objective | D2: Pre-conditions | E2: Test Steps | F2: Expected Result | G2: Actual Result | H2: Status | I2: Priority
A3: TC_COURSE_01 | B3: Get Public Course List | C3: Verify that a user can browse the paginated list of all published courses on the platform | D3: 1. The actor is logged in as a regular User. 2. At least one course with status `APPROVED` exists. | E3: 1. Log in as a User. 2. Navigate to the Course Catalog / Browse Courses page. | F3: - The system returns HTTP 200 OK. - A paginated list of approved courses is returned, each including title, thumbnail, instructor name, average rating, price, and total enrollments. | G3: As expected: The system returns HTTP 200 OK. - A paginated list of approved courses is returned, each including title, thumbnail, instructor name, average rating, price, and total enrollments. | H3: Pass | I3: High
A4: TC_COURSE_02 | B4: Get Course Detail | C4: Verify that a user can view the full detail page of a specific course | D4: 1. The actor is logged in as a regular User. 2. The target course (ID: 1) exists with status `APPROVED`. | E4: 1. Log in as a User. 2. Browse to a specific course and click on it. | F4: - The system returns HTTP 200 OK. - The full course detail is returned, including description, what-you-will-learn, prerequisites, instructor profile, total lessons, and price. | G4: As expected: The system returns HTTP 200 OK. - The full course detail is returned, including description, what-you-will-learn, prerequisites, instructor profile, total lessons, and price. | H4: Pass | I4: High
A5: TC_COURSE_03 | B5: Get Course Curriculum | C5: Verify that a user can view the chapter and lesson structure of a course before enrolling | D5: 1. The actor is logged in as a regular User. 2. The target course (ID: 1) is approved and has at least one chapter with lessons. | E5: 1. Log in as a User. 2. Navigate to the course detail page. 3. Scroll to or click the "Curriculum" tab. | F5: - The system returns HTTP 200 OK. - A structured list of chapters is returned, each containing its lesson titles, types (video/quiz/problem), and duration. | G5: As expected: The system returns HTTP 200 OK. - A structured list of chapters is returned, each containing its lesson titles, types (video/quiz/problem), and duration. | H5: Pass | I5: Medium
A6: TC_COURSE_04 | B6: Get Course Reviews | C6: Verify that a user can view ratings and reviews submitted for a course | D6: 1. The actor is logged in as a regular User. 2. The target course (ID: 1) has at least one review. | E6: 1. Log in as a User. 2. Navigate to the course detail page. 3. Click the "Reviews" tab. | F6: - The system returns HTTP 200 OK. - The response includes the overall `averageRating`, `totalReviews` count, and a list of individual user reviews with star rating and comment content. | G6: As expected: The system returns HTTP 200 OK. - The response includes the overall `averageRating`, `totalReviews` count, and a list of individual user reviews with star rating and comment content. | H6: Pass | I6: Medium
A7: TC_COURSE_05 | B7: Submit Course Review | C7: Verify that an enrolled user can submit a star rating and written review for a course they have access to | D7: 1. The actor is logged in as a regular User. 2. The user is enrolled in the target course (ID: 1). | E7: 1. Log in as a User. 2. Navigate to the course page for an enrolled course. 3. Go to the Reviews tab. 4. Select a star rating (e.g., 5 stars) and write a comment. 5. Submit the review. | F7: - The system returns HTTP 200 OK. - The response message is "Review submitted successfully". - The new review is saved to the database and the course's `averageRating` and `totalReviews` are recalculated. | G7: Failed: The review is saved successfully, but the course's averageRating was not recalculated because the asynchronous recalculation task failed with a NullPointerException in RatingService.java line 112 when handling zero-star review inputs. | H7: Fail | I7: High
A8: TC_COURSE_06 | B8: Get Learning Detail | C8: Verify that an enrolled user can access the learning-specific details of their course | D8: 1. The actor is logged in as a regular User. 2. The user is actively enrolled in the target course (enrollment status: `ACTIVE`). | E8: 1. Log in as a User. 2. Navigate to "My Courses" and select an enrolled course. 3. Enter the learning view. | F8: - The system returns HTTP 200 OK. - The response contains the course's learning-specific data including the user's overall progress percentage. | G8: As expected: The system returns HTTP 200 OK. - The response contains the course's learning-specific data including the user's overall progress percentage. | H8: Pass | I8: Medium
A9: TC_COURSE_07 | B9: Get Learning Curriculum (with Progress) | C9: Verify that an enrolled user can see the course curriculum with their completion progress tracked | D9: 1. The actor is logged in as a regular User. 2. The user is enrolled and has completed at least one lesson. | E9: 1. Log in as a User. 2. Navigate to the course learning view. 3. View the curriculum panel. | F9: - The system returns HTTP 200 OK. - The curriculum is returned with each lesson marked as either "completed" or "not completed" based on the user's actual progress. | G9: As expected: The system returns HTTP 200 OK. - The curriculum is returned with each lesson marked as either "completed" or "not completed" based on the user's actual progress. | H9: Pass | I9: Medium
A10: TC_COURSE_08 | B10: Get Lesson Detail (Learning) | C10: Verify that an enrolled user can open and view the content of a specific lesson | D10: 1. The actor is logged in as a regular User. 2. The user is enrolled in the course containing the target lesson (Lesson ID: 200). 3. The lesson status is `ACTIVE`. | E10: 1. Log in as a User. 2. Navigate to the course learning view. 3. Click on a specific lesson from the curriculum. | F10: - The system returns HTTP 200 OK. - The lesson detail is returned, including the lesson title, theory content (HTML), video URL, and any associated coding problems. | G10: As expected: The system returns HTTP 200 OK. - The lesson detail is returned, including the lesson title, theory content (HTML), video URL, and any associated coding problems. | H10: Pass | I10: High
A11: TC_COURSE_09 | B11: Get Lesson Comments | C11: Verify that a user can view the Q&A discussion thread for a specific lesson | D11: 1. The actor is logged in as a regular User. 2. The target lesson (ID: 200) has at least one comment or reply. | E11: 1. Log in as a User. 2. Navigate to a lesson's learning page. 3. Scroll to or click the "Comments / Q&A" section. | F11: - The system returns HTTP 200 OK. - A list of root-level comments is returned, with each comment also containing its nested replies. | G11: As expected: The system returns HTTP 200 OK. - A list of root-level comments is returned, with each comment also containing its nested replies. | H11: Pass | I11: Medium
A12: TC_COURSE_10 | B12: Add Lesson Comment | C12: Verify that an enrolled user can post a comment in the Q&A section of a lesson | D12: 1. The actor is logged in as a regular User. 2. The user is enrolled in the course containing the target lesson (ID: 200). | E12: 1. Log in as a User. 2. Navigate to a lesson's Q&A section. 3. Type a comment in the input box. 4. Click "Post" or "Submit". | F12: - The system returns HTTP 200 OK. - The response message is "Comment posted successfully". - The new comment appears in the lesson's Q&A thread. | G12: As expected: The system returns HTTP 200 OK. - The response message is "Comment posted successfully". - The new comment appears in the lesson's Q&A thread. | H12: Pass | I12: Medium
A13: TC_COURSE_11 | B13: Complete Lesson | C13: Verify that an enrolled user can mark a lesson as completed, and the system updates their progress | D13: 1. The actor is logged in as a regular User. 2. The user is enrolled in the course (ID: 1) and has not yet completed the target lesson (ID: 200). | E13: 1. Log in as a User. 2. Navigate to the lesson learning page. 3. Finish watching the video or reading the content. 4. Click "Mark as Complete" or complete the lesson interaction. | F13: - The system returns HTTP 200 OK. - The response message is "Lesson completed successfully". - A `LessonProgress` record is created for the user and lesson. - The `completedLessonsCount` for the user in this course is incremented. | G13: As expected: The system returns HTTP 200 OK. - The response message is "Lesson completed successfully". - A `LessonProgress` record is created for the user and lesson. - The `completedLessonsCount` for the user in this course is incremented. | H13: Pass | I13: High

Sheet QUIZ
A1: QUIZ MODULE — Test Case Specification
A2: Test Case ID | B2: Function Name | C2: Test Objective | D2: Pre-conditions | E2: Test Steps | F2: Expected Result | G2: Actual Result | H2: Status | I2: Priority
A3: TC_QUIZ_01 | B3: Get Quiz Details (Authenticated) | C3: Verify that an enrolled user can access and view the quiz associated with a specific lesson | D3: 1. The actor is logged in as a regular User. 2. The user is enrolled in the course containing the target lesson (ID: 10). 3. The lesson has an associated quiz. | E3: 1. Log in as a User. 2. Navigate to the lesson learning page that contains a quiz. 3. Click "Take Quiz" or navigate to the quiz tab. | F3: - The system returns HTTP 200 OK. - The response message is "Get quiz details successfully". - The quiz content is returned, including the quiz title and all questions with their shuffled answer options (correct answer is not marked). | G3: As expected: The system returns HTTP 200 OK. - The response message is "Get quiz details successfully". - The quiz content is returned, including the quiz title and all questions with their shuffled answer options (correct answer is not marked). | H3: Pass | I3: High
A4: TC_QUIZ_02 | B4: Get Quiz Details (Unauthenticated) | C4: Verify that the system denies access to quiz content for users who are not logged in | D4: 1. The actor is not logged in (guest user). 2. A quiz exists for the target lesson (ID: 10). | E4: 1. Without logging in, attempt to access a lesson's quiz page. | F4: - The system returns HTTP 401 Unauthorized. - No quiz content is returned. - The user is redirected to the login page. | G4: As expected: The system returns HTTP 401 Unauthorized. - No quiz content is returned. - The user is redirected to the login page. | H4: Pass | I4: High
A5: TC_QUIZ_03 | B5: Submit Quiz Answers (Authenticated) | C5: Verify that an enrolled user can submit their answers for a quiz and receive a score | D5: 1. The actor is logged in as a regular User. 2. The user is enrolled in the course and the quiz (ID: 20) is accessible. 3. The user has not yet submitted this quiz (or re-attempt is allowed). | E5: 1. Log in as a User. 2. Navigate to the quiz. 3. Answer all questions (or leave some blank). 4. Click "Submit Quiz". | F5: - The system returns HTTP 200 OK. - The response message is "Submit quiz successfully". - A `QuizAttempt` record is saved, storing the user's score and all submitted answers. - The final score and correct/incorrect breakdown are returned. | G5: Failed: The quiz submission returns HTTP 500 Internal Server Error instead of 200 OK because the system attempts to save a null score value in the QuizAttempt database record when a student submits an incomplete or empty quiz form. | H5: Fail | I5: High
A6: TC_QUIZ_04 | B6: Submit Quiz Answers (Unauthenticated) | C6: Verify that the system denies quiz submission for users who are not logged in | D6: 1. The actor is not logged in (guest user). | E6: 1. Without logging in, attempt to submit answers to a quiz. | F6: - The system returns HTTP 401 Unauthorized. - No quiz attempt is recorded. - The user is redirected to the login page. | G6: As expected: The system returns HTTP 401 Unauthorized. - No quiz attempt is recorded. - The user is redirected to the login page. | H6: Pass | I6: High

Sheet INSTRUCTOR
A1: INSTRUCTOR MODULE — Test Case Specification
A2: Test Case ID | B2: Function Name | C2: Test Objective | D2: Pre-conditions | E2: Test Steps | F2: Expected Result | G2: Actual Result | H2: Status | I2: Priority
A3: TC_INSTRUCTOR_01 | B3: Apply to Become Instructor | C3: Verify that an authenticated user can submit an application to become a course instructor on the platform | D3: 1. The actor is logged in as a regular User. 2. The user has not previously submitted an instructor application. 3. The user has a CV to upload and a valid introduction text. | E3: 1. Log in as a User. 2. Navigate to the "Become an Instructor" section. 3. Fill in the required fields: full name, major, bio, and upload a CV. 4. Submit the application. | F3: - The system returns HTTP 200 OK. - The application is saved to the database with status `PENDING`. - The AI evaluation pipeline is triggered to score the CV and introduction. - The user receives a confirmation that their application is under review. | G3: As expected: The system returns HTTP 200 OK. - The application is saved to the database with status `PENDING`. - The AI evaluation pipeline is triggered to score the CV and introduction. - The user receives a confirmation that their application is under review. | H3: Pass | I3: High
A4: TC_INSTRUCTOR_02 | B4: Get My Application Status | C4: Verify that an applicant can check the current status of their instructor application | D4: 1. The actor is logged in as a regular User. 2. The user has previously submitted an instructor application. | E4: 1. Log in as a User. 2. Navigate to the "My Application Status" section. | F4: - The system returns HTTP 200 OK. - The current application status is returned (e.g., `PENDING`, `APPROVED`, or `REJECTED`). - If available, the AI evaluation score and admin note are also included. | G4: As expected: The system returns HTTP 200 OK. - The current application status is returned (e.g., `PENDING`, `APPROVED`, or `REJECTED`). - If available, the AI evaluation score and admin note are also included. | H4: Pass | I4: Medium
A5: TC_INSTRUCTOR_03 | B5: Get Instructor's Own Courses | C5: Verify that an approved Instructor can view the list of all courses they have created | D5: 1. The actor is logged in with the `INSTRUCTOR` role. 2. The instructor has created at least one course. | E5: 1. Log in as an Instructor. 2. Navigate to the Instructor Dashboard > My Courses section. | F5: - The system returns HTTP 200 OK. - The response message is "Fetched instructor courses successfully". - A list of all courses owned by the instructor is returned, including title, status, total enrollments, and average rating. | G5: As expected: The system returns HTTP 200 OK. - The response message is "Fetched instructor courses successfully". - A list of all courses owned by the instructor is returned, including title, status, total enrollments, and average rating. | H5: Pass | I5: High
A6: TC_INSTRUCTOR_04 | B6: Create New Course | C6: Verify that an approved Instructor can create a new course draft on the platform | D6: 1. The actor is logged in with the `INSTRUCTOR` role. | E6: 1. Log in as an Instructor. 2. Navigate to Instructor Dashboard > Create New Course. 3. Fill in the required course information (title, short description, price, category, type). 4. Save the course. | F6: - The system returns HTTP 200 OK. - The response message is "Course created successfully". - A new course record is created in the database with status `DRAFTS` and linked to the instructor. | G6: As expected: The system returns HTTP 200 OK. - The response message is "Course created successfully". - A new course record is created in the database with status `DRAFTS` and linked to the instructor. | H6: Pass | I6: High
A7: TC_INSTRUCTOR_05 | B7: Upload Media File | C7: Verify that an Instructor can upload image or video media files for use in their course content | D7: 1. The actor is logged in with the `INSTRUCTOR` role. 2. A valid media file (image/video) is available for upload. 3. The Cloudinary media storage service is operational. | E7: 1. Log in as an Instructor. 2. Navigate to the course editor or media upload section. 3. Select and upload a file (e.g., thumbnail image). | F7: - The system returns HTTP 200 OK. - The response message is "File uploaded successfully". - A secure URL (`secureUrl`) pointing to the uploaded file on Cloudinary is returned and can be used in the course content. | G7: As expected: The system returns HTTP 200 OK. - The response message is "File uploaded successfully". - A secure URL (`secureUrl`) pointing to the uploaded file on Cloudinary is returned and can be used in the course content. | H7: Pass | I7: High
A8: TC_INSTRUCTOR_06 | B8: Get Course Detail (Instructor View) | C8: Verify that an Instructor can view the full editable detail of one of their own courses | D8: 1. The actor is logged in with the `INSTRUCTOR` role. 2. The target course (ID: 100) exists and belongs to this instructor. | E8: 1. Log in as an Instructor. 2. Navigate to My Courses. 3. Click on the target course to open its details. | F8: - The system returns HTTP 200 OK. - The response message is "Fetched instructor course detail successfully". - The full course detail is returned including all chapters, lessons, and current status. | G8: As expected: The system returns HTTP 200 OK. - The response message is "Fetched instructor course detail successfully". - The full course detail is returned including all chapters, lessons, and current status. | H8: Pass | I8: High
A9: TC_INSTRUCTOR_07 | B9: Update Course Draft | C9: Verify that an Instructor can edit and save changes to a course that is in draft status | D9: 1. The actor is logged in with the `INSTRUCTOR` role. 2. The target course (ID: 100) belongs to this instructor and has status `DRAFTS`. | E9: 1. Log in as an Instructor. 2. Navigate to the course editor for the target course. 3. Modify the course title, description, or other fields. 4. Click "Save Draft". | F9: - The system returns HTTP 200 OK. - The response message is "Course draft saved successfully." - The updated fields are persisted in the database. | G9: As expected: The system returns HTTP 200 OK. - The response message is "Course draft saved successfully." - The updated fields are persisted in the database. | H9: Pass | I9: High
A10: TC_INSTRUCTOR_08 | B10: Generate Testcases via AI | C10: Verify that an Instructor can use the AI-powered tool to auto-generate testcases for a coding problem in their course | D10: 1. The actor is logged in with the `INSTRUCTOR` role. 2. The Gemini AI service is operational. | E10: 1. Log in as an Instructor. 2. Navigate to the Testcase Generator tool. 3. Provide a problem description and a sample solution code. 4. Click "Generate". | F10: - The system returns HTTP 200 OK. - The response message is "Testcases generated successfully." - A list of generated testcase pairs (input data and expected output) is returned. | G10: Failed: The system returns HTTP 500 Internal Server Error (Gemini API quota exceeded or connection timeout). No testcases are generated or returned. | H10: Fail | I10: Medium
A11: TC_INSTRUCTOR_09 | B11: Submit Course for Review | C11: Verify that an Instructor can submit a completed draft course to the Admin review queue | D11: 1. The actor is logged in with the `INSTRUCTOR` role. 2. The target course (ID: 100) belongs to this instructor, has status `DRAFTS`, and has at least one active lesson. | E11: 1. Log in as an Instructor. 2. Navigate to the course editor. 3. Verify all content is complete. 4. Click "Submit for Review". | F11: - The system returns HTTP 200 OK. - The response message is "Course submitted for review successfully". - The course status is updated to `PENDING_AI` (then transitions to `PENDING_ADMIN` after passing AI moderation). - All lessons are set to `ACTIVE` status. | G11: As expected: The system returns HTTP 200 OK. - The response message is "Course submitted for review successfully". - The course status is updated to `PENDING_AI` (then transitions to `PENDING_ADMIN` after passing AI moderation). - All lessons are set to `ACTIVE` status. | H11: Pass | I11: High
A12: TC_INSTRUCTOR_10 | B12: Get Course Statistics | C12: Verify that an Instructor can view performance analytics for one of their published courses | D12: 1. The actor is logged in with the `INSTRUCTOR` role. 2. The target course (ID: 100) is published and has at least one enrolled student. | E12: 1. Log in as an Instructor. 2. Navigate to the course detail page. 3. Click the "Statistics" or "Analytics" tab. | F12: - The system returns HTTP 200 OK. - The response message is "Fetched course statistics successfully". - The analytics data includes total enrollments, average rating, completion rate (%), and revenue generated. | G12: As expected: The system returns HTTP 200 OK. - The response message is "Fetched course statistics successfully". - The analytics data includes total enrollments, average rating, completion rate (%), and revenue generated. | H12: Pass | I12: Medium
A13: TC_INSTRUCTOR_11 | B13: Get Revenue Summary | C13: Verify that an Instructor can view a financial summary of their total earnings for a selected time period | D13: 1. The actor is logged in with the `INSTRUCTOR` role. 2. The instructor has at least one completed order from their courses in the selected period. | E13: 1. Log in as an Instructor. 2. Navigate to the Revenue Dashboard. 3. Select a time period filter (e.g., "This Month"). | F13: - The system returns HTTP 200 OK. - The response includes: total gross revenue, platform commission fee deducted, and the instructor's net payout amount for the period. | G13: As expected: The system returns HTTP 200 OK. - The response includes: total gross revenue, platform commission fee deducted, and the instructor's net payout amount for the period. | H13: Pass | I13: High
... A18: TC_INSTRUCTOR_16 | B18: Submit Payout Request | C18: Verify that an Instructor with sufficient accumulated earnings can request a withdrawal to their bank account | D18: 1. The actor is logged in with the `INSTRUCTOR` role. 2. The instructor's available earnings balance is sufficient to cover the requested payout amount. 3. The instructor has not submitted a duplicate payout request for the same period. | E18: 1. Log in as an Instructor. 2. Navigate to Revenue > Request Payout. 3. Enter the desired amount, bank name, bank account number, and account holder name. 4. Confirm and submit. | F18: - The system returns HTTP 200 OK. - A new `PayoutRequest` record is created in the database with status `PENDING`. - The request is queued for Admin review and approval. | G18: As expected: The system returns HTTP 200 OK. - A new `PayoutRequest` record is created in the database with status `PENDING`. - The request is queued for Admin review and approval. | H18: Pass | I18: High

Sheet AI
A1: AI MODULE — Test Case Specification
A2: Test Case ID | B2: Function Name | C2: Test Objective | D2: Pre-conditions | E2: Test Steps | F2: Expected Result | G2: Actual Result | H2: Status | I2: Priority
A3: TC_AI_01 | B3: Generate Visualizer (Cache Hit) | C3: Verify that the system immediately returns a previously generated AI visualizer from cache without re-generating | D3: 1. The actor is logged in as a regular User. 2. An AI-generated visualizer already exists in the cache for the target problem (Problem ID: `prob123`). | E3: 1. Log in as a User. 2. Navigate to the problem page for a problem that has a cached visualizer. 3. Trigger the visualizer generation (without forcing re-generation). | F3: - The system returns HTTP 200 OK. - The response message is "Success (from cache)". - The cached visualizer data is returned immediately without triggering an AI generation job. - `fromCache = true` in the response. | G3: As expected: The system returns HTTP 200 OK. - The response message is "Success (from cache)". - The cached visualizer data is returned immediately without triggering an AI generation job. - `fromCache = true` in the response. | H3: Pass | I3: High
A4: TC_AI_02 | B4: Generate Visualizer (Cache Miss, Async) | C4: Verify that the system initiates an asynchronous AI generation job when no cached visualizer exists | D4: 1. The actor is logged in as a regular User. 2. No cached visualizer exists for the target problem. | E4: 1. Log in as a User. 2. Navigate to a problem page that has no cached visualizer. 3. Trigger the visualizer generation. | F4: - The system returns HTTP 202 Accepted. - A `jobId` is returned so the client can poll for status. - `fromCache = false` in the response. - A background AI generation job is started using the Gemini API. | G4: Failed: The background job fails to start and throws a standard HTTP 500. The Gemini API client raised a standard connection error: 'Connection aborted: RemoteDisconnected'. | H4: Fail | I4: High
A5: TC_AI_03 | B5: Check Visualization Job Status | C5: Verify that a user can check the processing status of an in-progress AI visualization job | D5: 1. The actor is logged in as a regular User. 2. A valid async job ID (e.g., `job123`) has been returned from a previous generate request. | E5: 1. Log in as a User. 2. Use the `jobId` to query the job status endpoint. | F5: - The system returns HTTP 200 OK. - The response contains the current job status (`PENDING`, `COMPLETED`, or `FAILED`) and, if completed, the resulting visualizer data. | G5: As expected: The system returns HTTP 200 OK. - The response contains the current job status (`PENDING`, `COMPLETED`, or `FAILED`) and, if completed, the resulting visualizer data. | H5: Pass | I5: High
